Process Process-1:
Process Process-2:
Traceback (most recent call last):
  File "/usr/lib/python3.8/multiprocessing/process.py", line 315, in _bootstrap
    self.run()
  File "/usr/lib/python3.8/multiprocessing/process.py", line 108, in run
    self._target(*self._args, **self._kwargs)
  File "/tmp/06e3d51c3af8423d92e88b8f7783d062.py", line 19, in worker
    generate_file(file_path, file_size)
  File "/tmp/06e3d51c3af8423d92e88b8f7783d062.py", line 13, in generate_file
    with open(file_path, 'w') as f:
  File "/usr/local/lib/python3.8/dist-packages/IPython/core/interactiveshell.py", line 284, in _modified_open
    return io_open(file, *args, **kwargs)
FileNotFoundError: [Errno 2] No such file or directory: '/home/coder/project/storage_test/files/large_file_0.txt'
Traceback (most recent call last):
  File "/usr/lib/python3.8/multiprocessing/process.py", line 315, in _bootstrap
    self.run()
  File "/usr/lib/python3.8/multiprocessing/process.py", line 108, in run
    self._target(*self._args, **self._kwargs)
  File "/tmp/06e3d51c3af8423d92e88b8f7783d062.py", line 19, in worker
    generate_file(file_path, file_size)
  File "/tmp/06e3d51c3af8423d92e88b8f7783d062.py", line 13, in generate_file
    with open(file_path, 'w') as f:
  File "/usr/local/lib/python3.8/dist-packages/IPython/core/interactiveshell.py", line 284, in _modified_open
    return io_open(file, *args, **kwargs)
FileNotFoundError: [Errno 2] No such file or directory: '/home/coder/project/storage_test/files/large_file_1.txt'
